[09/May/2014 01:34:57] "GET /api/test_showtime/ HTTP/1.1" 200 1343
Validating models...

running with lxml.etree
0 errors found
May 09, 2014 - 01:34:54
Django version 1.6.2, using settings 'settings'
Starting development server at http://0.0.0.0:8000/
Quit the server with CONTROL-C.
lat : None
lon : None
[09/May/2014 01:35:11] "GET /api/test_showtime/ HTTP/1.1" 200 1343
[09/May/2014 01:36:05] "GET /api/test_showtime/lat=123&lon=321 HTTP/1.1" 404 2250
[09/May/2014 01:37:38] "GET /api/test_showtime/lat=123 HTTP/1.1" 404 2214
[09/May/2014 01:37:42] "GET /api/test_showtime?lat=123 HTTP/1.1" 301 0
[09/May/2014 01:37:42] "GET /api/test_showtime/?lat=123 HTTP/1.1" 200 1343
[09/May/2014 01:37:51] "GET /api/test_showtime/?lat=123&lon=321 HTTP/1.1" 200 1343
[09/May/2014 01:40:14] "GET /api/all HTTP/1.1" 404 2160
[09/May/2014 01:40:19] "GET /api/theatre/all HTTP/1.1" 404 2184
[09/May/2014 01:40:22] "GET /api/theatres/all/ HTTP/1.1" 200 3859
[09/May/2014 02:00:46] "GET /api/theatres/all/ HTTP/1.1" 200 3859
Validating models...

running with lxml.etree
0 errors found
May 09, 2014 - 01:35:11
Django version 1.6.2, using settings 'settings'
Starting development server at http://0.0.0.0:8000/
Quit the server with CONTROL-C.
lat : None
lon : None
lat : 123
lon : None
lat : 123
lon : 321
[14/May/2014 02:18:38] "GET /api/theatres/all/ HTTP/1.1" 200 3859
Validating models...

running with lxml.etree
0 errors found
May 09, 2014 - 02:03:41
Django version 1.6.2, using settings 'settings'
Starting development server at http://0.0.0.0:8000/
Quit the server with CONTROL-C.
Validating models...

running with lxml.etree
0 errors found
May 14, 2014 - 02:33:15
Django version 1.6.2, using settings 'settings'
Starting development server at http://0.0.0.0:8000/
Quit the server with CONTROL-C.
Validating models...

running with lxml.etree
0 errors found
May 14, 2014 - 05:01:42
Django version 1.6.2, using settings 'settings'
Starting development server at http://0.0.0.0:8000/
Quit the server with CONTROL-C.
Validating models...

running with lxml.etree
0 errors found
May 14, 2014 - 05:02:11
Django version 1.6.2, using settings 'settings'
Starting development server at http://0.0.0.0:8000/
Quit the server with CONTROL-C.
Validating models...

running with lxml.etree
0 errors found
May 14, 2014 - 05:02:20
Django version 1.6.2, using settings 'settings'
Starting development server at http://0.0.0.0:8000/
Quit the server with CONTROL-C.
Unhandled exception in thread started by <function wrapper at 0x1f3aed8>
Validating models...

Traceback (most recent call last):
  File "/usr/lib/python2.6/site-packages/django/utils/autoreload.py", line 93, in wrapper
    fn(*args, **kwargs)
  File "/usr/lib/python2.6/site-packages/django/core/management/commands/runserver.py", line 101, in inner_run
    self.validate(display_num_errors=True)
  File "/usr/lib/python2.6/site-packages/django/core/management/base.py", line 310, in validate
    num_errors = get_validation_errors(s, app)
  File "/usr/lib/python2.6/site-packages/django/core/management/validation.py", line 34, in get_validation_errors
    for (app_name, error) in get_app_errors().items():
  File "/usr/lib/python2.6/site-packages/django/db/models/loading.py", line 196, in get_app_errors
    self._populate()
  File "/usr/lib/python2.6/site-packages/django/db/models/loading.py", line 75, in _populate
    self.load_app(app_name, True)
  File "/usr/lib/python2.6/site-packages/django/db/models/loading.py", line 99, in load_app
    models = import_module('%s.models' % app_name)
  File "/usr/lib/python2.6/site-packages/django/utils/importlib.py", line 40, in import_module
    __import__(name)
  File "/home/ec2-user/django15/xmlparser/models.py", line 33
    class TheatreMovieManager(models.Manager):
    ^
IndentationError: expected an indented block
Validating models...

running with lxml.etree
0 errors found
May 14, 2014 - 05:28:00
Django version 1.6.2, using settings 'settings'
Starting development server at http://0.0.0.0:8000/
Quit the server with CONTROL-C.
Validating models...

running with lxml.etree
0 errors found
May 14, 2014 - 05:28:30
Django version 1.6.2, using settings 'settings'
Starting development server at http://0.0.0.0:8000/
Quit the server with CONTROL-C.
Validating models...

running with lxml.etree
0 errors found
May 14, 2014 - 05:29:09
Django version 1.6.2, using settings 'settings'
Starting development server at http://0.0.0.0:8000/
Quit the server with CONTROL-C.
Validating models...

running with lxml.etree
0 errors found
May 14, 2014 - 05:32:59
Django version 1.6.2, using settings 'settings'
Starting development server at http://0.0.0.0:8000/
Quit the server with CONTROL-C.
Validating models...

running with lxml.etree
0 errors found
May 14, 2014 - 05:33:23
Django version 1.6.2, using settings 'settings'
Starting development server at http://0.0.0.0:8000/
Quit the server with CONTROL-C.
Validating models...

running with lxml.etree
0 errors found
May 14, 2014 - 05:34:15
Django version 1.6.2, using settings 'settings'
Starting development server at http://0.0.0.0:8000/
Quit the server with CONTROL-C.
Validating models...

running with lxml.etree
0 errors found
May 14, 2014 - 05:51:18
Django version 1.6.2, using settings 'settings'
Starting development server at http://0.0.0.0:8000/
Quit the server with CONTROL-C.
Validating models...

running with lxml.etree
0 errors found
May 14, 2014 - 06:13:48
Django version 1.6.2, using settings 'settings'
Starting development server at http://0.0.0.0:8000/
Quit the server with CONTROL-C.
Validating models...

running with lxml.etree
0 errors found
May 14, 2014 - 06:13:53
Django version 1.6.2, using settings 'settings'
Starting development server at http://0.0.0.0:8000/
Quit the server with CONTROL-C.
Validating models...

running with lxml.etree
0 errors found
May 14, 2014 - 06:14:09
Django version 1.6.2, using settings 'settings'
Starting development server at http://0.0.0.0:8000/
Quit the server with CONTROL-C.
Validating models...

running with lxml.etree
0 errors found
May 14, 2014 - 06:14:13
Django version 1.6.2, using settings 'settings'
Starting development server at http://0.0.0.0:8000/
Quit the server with CONTROL-C.
Unhandled exception in thread started by <function wrapper at 0x20a1ed8>
Traceback (most recent call last):
  File "/usr/lib/python2.6/site-packages/django/utils/autoreload.py", line 100, in wrapper
    filename = traceback.extract_tb(tb)[-1][0]
TypeError: 'NoneType' object is not callable
Validating models...

running with lxml.etree
0 errors found
May 14, 2014 - 06:16:55
Django version 1.6.2, using settings 'settings'
Starting development server at http://0.0.0.0:8000/
Quit the server with CONTROL-C.
Unhandled exception in thread started by <function wrapper at 0xb3ded8>
Traceback (most recent call last):
  File "/usr/lib/python2.6/site-packages/django/utils/autoreload.py", line 100, in wrapper
    filename = traceback.extract_tb(tb)[-1][0]
TypeError: 'NoneType' object is not callable
Validating models...

running with lxml.etree
0 errors found
May 14, 2014 - 06:19:46
Django version 1.6.2, using settings 'settings'
Starting development server at http://0.0.0.0:8000/
Quit the server with CONTROL-C.
Unhandled exception in thread started by <function wrapper at 0x2822ed8>
Validating models...

Traceback (most recent call last):
  File "/usr/lib/python2.6/site-packages/django/utils/autoreload.py", line 93, in wrapper
    fn(*args, **kwargs)
  File "/usr/lib/python2.6/site-packages/django/core/management/commands/runserver.py", line 101, in inner_run
    self.validate(display_num_errors=True)
  File "/usr/lib/python2.6/site-packages/django/core/management/base.py", line 310, in validate
    num_errors = get_validation_errors(s, app)
  File "/usr/lib/python2.6/site-packages/django/core/management/validation.py", line 34, in get_validation_errors
    for (app_name, error) in get_app_errors().items():
  File "/usr/lib/python2.6/site-packages/django/db/models/loading.py", line 196, in get_app_errors
    self._populate()
  File "/usr/lib/python2.6/site-packages/django/db/models/loading.py", line 75, in _populate
    self.load_app(app_name, True)
  File "/usr/lib/python2.6/site-packages/django/db/models/loading.py", line 99, in load_app
    models = import_module('%s.models' % app_name)
  File "/usr/lib/python2.6/site-packages/django/utils/importlib.py", line 40, in import_module
    __import__(name)
  File "/home/ec2-user/django15/xmlparser/models.py", line 98
    class TheatreManager(models.Manager):
    ^
IndentationError: expected an indented block
Unhandled exception in thread started by <function wrapper at 0x27cced8>
Validating models...

Traceback (most recent call last):
  File "/usr/lib/python2.6/site-packages/django/utils/autoreload.py", line 93, in wrapper
    fn(*args, **kwargs)
  File "/usr/lib/python2.6/site-packages/django/core/management/commands/runserver.py", line 101, in inner_run
    self.validate(display_num_errors=True)
  File "/usr/lib/python2.6/site-packages/django/core/management/base.py", line 310, in validate
    num_errors = get_validation_errors(s, app)
  File "/usr/lib/python2.6/site-packages/django/core/management/validation.py", line 34, in get_validation_errors
    for (app_name, error) in get_app_errors().items():
  File "/usr/lib/python2.6/site-packages/django/db/models/loading.py", line 196, in get_app_errors
    self._populate()
  File "/usr/lib/python2.6/site-packages/django/db/models/loading.py", line 75, in _populate
    self.load_app(app_name, True)
  File "/usr/lib/python2.6/site-packages/django/db/models/loading.py", line 99, in load_app
    models = import_module('%s.models' % app_name)
  File "/usr/lib/python2.6/site-packages/django/utils/importlib.py", line 40, in import_module
    __import__(name)
  File "/home/ec2-user/django15/xmlparser/models.py", line 97
    cursor = connection.cursor()
         ^
IndentationError: expected an indented block
Unhandled exception in thread started by <function wrapper at 0x2564ed8>
Validating models...

Traceback (most recent call last):
  File "/usr/lib/python2.6/site-packages/django/utils/autoreload.py", line 93, in wrapper
    fn(*args, **kwargs)
  File "/usr/lib/python2.6/site-packages/django/core/management/commands/runserver.py", line 101, in inner_run
    self.validate(display_num_errors=True)
  File "/usr/lib/python2.6/site-packages/django/core/management/base.py", line 310, in validate
    num_errors = get_validation_errors(s, app)
  File "/usr/lib/python2.6/site-packages/django/core/management/validation.py", line 34, in get_validation_errors
    for (app_name, error) in get_app_errors().items():
  File "/usr/lib/python2.6/site-packages/django/db/models/loading.py", line 196, in get_app_errors
    self._populate()
  File "/usr/lib/python2.6/site-packages/django/db/models/loading.py", line 75, in _populate
    self.load_app(app_name, True)
  File "/usr/lib/python2.6/site-packages/django/db/models/loading.py", line 99, in load_app
    models = import_module('%s.models' % app_name)
  File "/usr/lib/python2.6/site-packages/django/utils/importlib.py", line 40, in import_module
    __import__(name)
  File "/home/ec2-user/django15/xmlparser/models.py", line 97
    cursor = connection.cursor()
         ^
IndentationError: expected an indented block
Unhandled exception in thread started by <function wrapper at 0xbdfed8>
Validating models...

Traceback (most recent call last):
  File "/usr/lib/python2.6/site-packages/django/utils/autoreload.py", line 93, in wrapper
    fn(*args, **kwargs)
  File "/usr/lib/python2.6/site-packages/django/core/management/commands/runserver.py", line 101, in inner_run
    self.validate(display_num_errors=True)
  File "/usr/lib/python2.6/site-packages/django/core/management/base.py", line 310, in validate
    num_errors = get_validation_errors(s, app)
  File "/usr/lib/python2.6/site-packages/django/core/management/validation.py", line 34, in get_validation_errors
    for (app_name, error) in get_app_errors().items():
  File "/usr/lib/python2.6/site-packages/django/db/models/loading.py", line 196, in get_app_errors
    self._populate()
  File "/usr/lib/python2.6/site-packages/django/db/models/loading.py", line 75, in _populate
    self.load_app(app_name, True)
  File "/usr/lib/python2.6/site-packages/django/db/models/loading.py", line 99, in load_app
    models = import_module('%s.models' % app_name)
  File "/usr/lib/python2.6/site-packages/django/utils/importlib.py", line 40, in import_module
    __import__(name)
  File "/home/ec2-user/django15/xmlparser/models.py", line 97
    cursor = connection.cursor()
         ^
IndentationError: expected an indented block
Validating models...

running with lxml.etree
0 errors found
May 14, 2014 - 06:24:38
Django version 1.6.2, using settings 'settings'
Starting development server at http://0.0.0.0:8000/
Quit the server with CONTROL-C.
Validating models...

running with lxml.etree
0 errors found
May 14, 2014 - 06:24:47
Django version 1.6.2, using settings 'settings'
Starting development server at http://0.0.0.0:8000/
Quit the server with CONTROL-C.
Validating models...

running with lxml.etree
0 errors found
May 14, 2014 - 06:26:45
Django version 1.6.2, using settings 'settings'
Starting development server at http://0.0.0.0:8000/
Quit the server with CONTROL-C.
Validating models...

running with lxml.etree
0 errors found
May 14, 2014 - 06:26:51
Django version 1.6.2, using settings 'settings'
Starting development server at http://0.0.0.0:8000/
Quit the server with CONTROL-C.
Unhandled exception in thread started by <function wrapper at 0x16c6ed8>
Traceback (most recent call last):
  File "/usr/lib/python2.6/site-packages/django/utils/autoreload.py", line 100, in wrapper
    filename = traceback.extract_tb(tb)[-1][0]
TypeError: 'NoneType' object is not callable
Validating models...

running with lxml.etree
0 errors found
May 14, 2014 - 06:28:38
Django version 1.6.2, using settings 'settings'
Starting development server at http://0.0.0.0:8000/
Quit the server with CONTROL-C.
Validating models...

running with lxml.etree
0 errors found
May 14, 2014 - 06:38:45
Django version 1.6.2, using settings 'settings'
Starting development server at http://0.0.0.0:8000/
Quit the server with CONTROL-C.
Validating models...

running with lxml.etree
0 errors found
May 14, 2014 - 06:44:33
Django version 1.6.2, using settings 'settings'
Starting development server at http://0.0.0.0:8000/
Quit the server with CONTROL-C.
Validating models...

running with lxml.etree
0 errors found
May 14, 2014 - 06:45:56
Django version 1.6.2, using settings 'settings'
Starting development server at http://0.0.0.0:8000/
Quit the server with CONTROL-C.
Validating models...

running with lxml.etree
0 errors found
May 14, 2014 - 06:46:02
Django version 1.6.2, using settings 'settings'
Starting development server at http://0.0.0.0:8000/
Quit the server with CONTROL-C.
Unhandled exception in thread started by <function wrapper at 0x1619ed8>
Traceback (most recent call last):
  File "/usr/lib/python2.6/site-packages/django/utils/autoreload.py", line 96, in wrapper
    et, ev, tb = sys.exc_info()
AttributeError: 'NoneType' object has no attribute 'exc_info'
Validating models...

running with lxml.etree
0 errors found
May 14, 2014 - 06:46:14
Django version 1.6.2, using settings 'settings'
Starting development server at http://0.0.0.0:8000/
Quit the server with CONTROL-C.
Unhandled exception in thread started by <function wrapper at 0x19c1ed8>
Validating models...

Traceback (most recent call last):
  File "/usr/lib/python2.6/site-packages/django/utils/autoreload.py", line 93, in wrapper
    fn(*args, **kwargs)
  File "/usr/lib/python2.6/site-packages/django/core/management/commands/runserver.py", line 101, in inner_run
    self.validate(display_num_errors=True)
  File "/usr/lib/python2.6/site-packages/django/core/management/base.py", line 310, in validate
    num_errors = get_validation_errors(s, app)
  File "/usr/lib/python2.6/site-packages/django/core/management/validation.py", line 34, in get_validation_errors
    for (app_name, error) in get_app_errors().items():
  File "/usr/lib/python2.6/site-packages/django/db/models/loading.py", line 196, in get_app_errors
    self._populate()
  File "/usr/lib/python2.6/site-packages/django/db/models/loading.py", line 75, in _populate
    self.load_app(app_name, True)
  File "/usr/lib/python2.6/site-packages/django/db/models/loading.py", line 99, in load_app
    models = import_module('%s.models' % app_name)
  File "/usr/lib/python2.6/site-packages/django/utils/importlib.py", line 40, in import_module
    __import__(name)
  File "/home/ec2-user/django15/xmlparser/models.py", line 96
    with transaction.atomic():
    ^
IndentationError: unexpected indent
Validating models...

running with lxml.etree
0 errors found
May 14, 2014 - 06:50:34
Django version 1.6.2, using settings 'settings'
Starting development server at http://0.0.0.0:8000/
Quit the server with CONTROL-C.
Validating models...

running with lxml.etree
0 errors found
May 14, 2014 - 06:52:53
Django version 1.6.2, using settings 'settings'
Starting development server at http://0.0.0.0:8000/
Quit the server with CONTROL-C.
Validating models...

running with lxml.etree
0 errors found
May 14, 2014 - 06:53:48
Django version 1.6.2, using settings 'settings'
Starting development server at http://0.0.0.0:8000/
Quit the server with CONTROL-C.
Validating models...

running with lxml.etree
0 errors found
May 14, 2014 - 06:54:25
Django version 1.6.2, using settings 'settings'
Starting development server at http://0.0.0.0:8000/
Quit the server with CONTROL-C.
Validating models...

running with lxml.etree
0 errors found
May 14, 2014 - 07:11:03
Django version 1.6.2, using settings 'settings'
Starting development server at http://0.0.0.0:8000/
Quit the server with CONTROL-C.
Validating models...

running with lxml.etree
0 errors found
May 14, 2014 - 07:23:09
Django version 1.6.2, using settings 'settings'
Starting development server at http://0.0.0.0:8000/
Quit the server with CONTROL-C.
Validating models...

running with lxml.etree
0 errors found
May 14, 2014 - 07:23:34
Django version 1.6.2, using settings 'settings'
Starting development server at http://0.0.0.0:8000/
Quit the server with CONTROL-C.
Validating models...

running with lxml.etree
0 errors found
May 14, 2014 - 07:28:11
Django version 1.6.2, using settings 'settings'
Starting development server at http://0.0.0.0:8000/
Quit the server with CONTROL-C.
Validating models...

running with lxml.etree
0 errors found
May 14, 2014 - 07:31:32
Django version 1.6.2, using settings 'settings'
Starting development server at http://0.0.0.0:8000/
Quit the server with CONTROL-C.
Validating models...

running with lxml.etree
0 errors found
May 14, 2014 - 07:33:15
Django version 1.6.2, using settings 'settings'
Starting development server at http://0.0.0.0:8000/
Quit the server with CONTROL-C.
Validating models...

running with lxml.etree
0 errors found
May 14, 2014 - 07:34:03
Django version 1.6.2, using settings 'settings'
Starting development server at http://0.0.0.0:8000/
Quit the server with CONTROL-C.
Validating models...

running with lxml.etree
0 errors found
May 14, 2014 - 07:35:34
Django version 1.6.2, using settings 'settings'
Starting development server at http://0.0.0.0:8000/
Quit the server with CONTROL-C.
Validating models...

running with lxml.etree
0 errors found
May 14, 2014 - 07:35:37
Django version 1.6.2, using settings 'settings'
Starting development server at http://0.0.0.0:8000/
Quit the server with CONTROL-C.
Validating models...

running with lxml.etree
0 errors found
May 14, 2014 - 07:36:17
Django version 1.6.2, using settings 'settings'
Starting development server at http://0.0.0.0:8000/
Quit the server with CONTROL-C.
Validating models...

running with lxml.etree
0 errors found
May 14, 2014 - 07:37:20
Django version 1.6.2, using settings 'settings'
Starting development server at http://0.0.0.0:8000/
Quit the server with CONTROL-C.
Validating models...

running with lxml.etree
0 errors found
May 14, 2014 - 07:37:43
Django version 1.6.2, using settings 'settings'
Starting development server at http://0.0.0.0:8000/
Quit the server with CONTROL-C.
Validating models...

running with lxml.etree
0 errors found
May 14, 2014 - 07:38:00
Django version 1.6.2, using settings 'settings'
Starting development server at http://0.0.0.0:8000/
Quit the server with CONTROL-C.
Validating models...

running with lxml.etree
0 errors found
May 14, 2014 - 07:38:24
Django version 1.6.2, using settings 'settings'
Starting development server at http://0.0.0.0:8000/
Quit the server with CONTROL-C.
Validating models...

running with lxml.etree
0 errors found
May 14, 2014 - 07:38:39
Django version 1.6.2, using settings 'settings'
Starting development server at http://0.0.0.0:8000/
Quit the server with CONTROL-C.
Validating models...

running with lxml.etree
0 errors found
May 14, 2014 - 07:38:51
Django version 1.6.2, using settings 'settings'
Starting development server at http://0.0.0.0:8000/
Quit the server with CONTROL-C.
Validating models...

running with lxml.etree
0 errors found
May 14, 2014 - 07:39:20
Django version 1.6.2, using settings 'settings'
Starting development server at http://0.0.0.0:8000/
Quit the server with CONTROL-C.
Unhandled exception in thread started by <function wrapper at 0xa2ded8>
Traceback (most recent call last):
  File "/usr/lib/python2.6/site-packages/django/utils/autoreload.py", line 100, in wrapper
    filename = traceback.extract_tb(tb)[-1][0]
TypeError: 'NoneType' object is not callable
Validating models...

running with lxml.etree
0 errors found
May 14, 2014 - 07:47:15
Django version 1.6.2, using settings 'settings'
Starting development server at http://0.0.0.0:8000/
Quit the server with CONTROL-C.
Validating models...

running with lxml.etree
0 errors found
May 14, 2014 - 07:47:22
Django version 1.6.2, using settings 'settings'
Starting development server at http://0.0.0.0:8000/
Quit the server with CONTROL-C.
Validating models...

running with lxml.etree
0 errors found
May 14, 2014 - 07:49:32
Django version 1.6.2, using settings 'settings'
Starting development server at http://0.0.0.0:8000/
Quit the server with CONTROL-C.
Validating models...

running with lxml.etree
0 errors found
May 14, 2014 - 07:50:10
Django version 1.6.2, using settings 'settings'
Starting development server at http://0.0.0.0:8000/
Quit the server with CONTROL-C.
Validating models...

running with lxml.etree
0 errors found
May 14, 2014 - 07:51:08
Django version 1.6.2, using settings 'settings'
Starting development server at http://0.0.0.0:8000/
Quit the server with CONTROL-C.
Validating models...

running with lxml.etree
0 errors found
May 14, 2014 - 08:06:04
Django version 1.6.2, using settings 'settings'
Starting development server at http://0.0.0.0:8000/
Quit the server with CONTROL-C.
Validating models...

running with lxml.etree
0 errors found
May 14, 2014 - 08:06:27
Django version 1.6.2, using settings 'settings'
Starting development server at http://0.0.0.0:8000/
Quit the server with CONTROL-C.
Validating models...

running with lxml.etree
0 errors found
May 14, 2014 - 08:06:43
Django version 1.6.2, using settings 'settings'
Starting development server at http://0.0.0.0:8000/
Quit the server with CONTROL-C.
Validating models...

running with lxml.etree
0 errors found
May 14, 2014 - 08:07:58
Django version 1.6.2, using settings 'settings'
Starting development server at http://0.0.0.0:8000/
Quit the server with CONTROL-C.
Validating models...

running with lxml.etree
0 errors found
May 14, 2014 - 08:10:10
Django version 1.6.2, using settings 'settings'
Starting development server at http://0.0.0.0:8000/
Quit the server with CONTROL-C.
Validating models...

running with lxml.etree
0 errors found
May 14, 2014 - 08:14:31
Django version 1.6.2, using settings 'settings'
Starting development server at http://0.0.0.0:8000/
Quit the server with CONTROL-C.
Validating models...

running with lxml.etree
0 errors found
May 14, 2014 - 08:14:51
Django version 1.6.2, using settings 'settings'
Starting development server at http://0.0.0.0:8000/
Quit the server with CONTROL-C.
Validating models...

running with lxml.etree
0 errors found
May 14, 2014 - 08:16:03
Django version 1.6.2, using settings 'settings'
Starting development server at http://0.0.0.0:8000/
Quit the server with CONTROL-C.
Validating models...

running with lxml.etree
0 errors found
May 14, 2014 - 08:16:17
Django version 1.6.2, using settings 'settings'
Starting development server at http://0.0.0.0:8000/
Quit the server with CONTROL-C.
Validating models...

running with lxml.etree
0 errors found
May 14, 2014 - 08:17:49
Django version 1.6.2, using settings 'settings'
Starting development server at http://0.0.0.0:8000/
Quit the server with CONTROL-C.
Validating models...

running with lxml.etree
0 errors found
May 14, 2014 - 08:18:58
Django version 1.6.2, using settings 'settings'
Starting development server at http://0.0.0.0:8000/
Quit the server with CONTROL-C.
Validating models...

running with lxml.etree
0 errors found
May 14, 2014 - 08:19:41
Django version 1.6.2, using settings 'settings'
Starting development server at http://0.0.0.0:8000/
Quit the server with CONTROL-C.
Validating models...

running with lxml.etree
0 errors found
May 14, 2014 - 08:22:41
Django version 1.6.2, using settings 'settings'
Starting development server at http://0.0.0.0:8000/
Quit the server with CONTROL-C.
Validating models...

running with lxml.etree
0 errors found
May 14, 2014 - 08:26:58
Django version 1.6.2, using settings 'settings'
Starting development server at http://0.0.0.0:8000/
Quit the server with CONTROL-C.
Validating models...

running with lxml.etree
0 errors found
May 14, 2014 - 08:27:04
Django version 1.6.2, using settings 'settings'
Starting development server at http://0.0.0.0:8000/
Quit the server with CONTROL-C.
Validating models...

running with lxml.etree
0 errors found
May 14, 2014 - 08:27:09
Django version 1.6.2, using settings 'settings'
Starting development server at http://0.0.0.0:8000/
Quit the server with CONTROL-C.
Validating models...

running with lxml.etree
0 errors found
May 14, 2014 - 08:27:17
Django version 1.6.2, using settings 'settings'
Starting development server at http://0.0.0.0:8000/
Quit the server with CONTROL-C.
Validating models...

running with lxml.etree
0 errors found
May 14, 2014 - 08:27:23
Django version 1.6.2, using settings 'settings'
Starting development server at http://0.0.0.0:8000/
Quit the server with CONTROL-C.
Validating models...

running with lxml.etree
0 errors found
May 14, 2014 - 08:27:32
Django version 1.6.2, using settings 'settings'
Starting development server at http://0.0.0.0:8000/
Quit the server with CONTROL-C.
Validating models...

running with lxml.etree
0 errors found
May 14, 2014 - 08:27:54
Django version 1.6.2, using settings 'settings'
Starting development server at http://0.0.0.0:8000/
Quit the server with CONTROL-C.
Validating models...

running with lxml.etree
0 errors found
May 14, 2014 - 08:28:29
Django version 1.6.2, using settings 'settings'
Starting development server at http://0.0.0.0:8000/
Quit the server with CONTROL-C.
Validating models...

running with lxml.etree
0 errors found
May 14, 2014 - 08:30:04
Django version 1.6.2, using settings 'settings'
Starting development server at http://0.0.0.0:8000/
Quit the server with CONTROL-C.
Validating models...

running with lxml.etree
0 errors found
May 14, 2014 - 08:31:18
Django version 1.6.2, using settings 'settings'
Starting development server at http://0.0.0.0:8000/
Quit the server with CONTROL-C.
Validating models...

running with lxml.etree
0 errors found
May 14, 2014 - 08:32:50
Django version 1.6.2, using settings 'settings'
Starting development server at http://0.0.0.0:8000/
Quit the server with CONTROL-C.
Validating models...

running with lxml.etree
0 errors found
May 14, 2014 - 08:32:59
Django version 1.6.2, using settings 'settings'
Starting development server at http://0.0.0.0:8000/
Quit the server with CONTROL-C.
Validating models...

running with lxml.etree
0 errors found
May 14, 2014 - 08:40:15
Django version 1.6.2, using settings 'settings'
Starting development server at http://0.0.0.0:8000/
Quit the server with CONTROL-C.
Validating models...

running with lxml.etree
0 errors found
May 14, 2014 - 08:41:58
Django version 1.6.2, using settings 'settings'
Starting development server at http://0.0.0.0:8000/
Quit the server with CONTROL-C.
Validating models...

running with lxml.etree
0 errors found
May 14, 2014 - 08:42:04
Django version 1.6.2, using settings 'settings'
Starting development server at http://0.0.0.0:8000/
Quit the server with CONTROL-C.
Validating models...

running with lxml.etree
0 errors found
May 14, 2014 - 08:42:49
Django version 1.6.2, using settings 'settings'
Starting development server at http://0.0.0.0:8000/
Quit the server with CONTROL-C.
Validating models...

running with lxml.etree
0 errors found
May 14, 2014 - 08:47:13
Django version 1.6.2, using settings 'settings'
Starting development server at http://0.0.0.0:8000/
Quit the server with CONTROL-C.
Validating models...

running with lxml.etree
0 errors found
May 14, 2014 - 08:47:40
Django version 1.6.2, using settings 'settings'
Starting development server at http://0.0.0.0:8000/
Quit the server with CONTROL-C.
Unhandled exception in thread started by <function wrapper at 0x1fe0ed8>
Traceback (most recent call last):
  File "/usr/lib/python2.6/site-packages/django/utils/autoreload.py", line 100, in wrapper
    filename = traceback.extract_tb(tb)[-1][0]
TypeError: 'NoneType' object is not callable
Validating models...

running with lxml.etree
0 errors found
May 14, 2014 - 08:49:23
Django version 1.6.2, using settings 'settings'
Starting development server at http://0.0.0.0:8000/
Quit the server with CONTROL-C.
Validating models...

running with lxml.etree
0 errors found
May 14, 2014 - 08:49:41
Django version 1.6.2, using settings 'settings'
Starting development server at http://0.0.0.0:8000/
Quit the server with CONTROL-C.
Validating models...

running with lxml.etree
0 errors found
May 14, 2014 - 08:50:06
Django version 1.6.2, using settings 'settings'
Starting development server at http://0.0.0.0:8000/
Quit the server with CONTROL-C.
Validating models...

running with lxml.etree
0 errors found
May 14, 2014 - 08:54:17
Django version 1.6.2, using settings 'settings'
Starting development server at http://0.0.0.0:8000/
Quit the server with CONTROL-C.
Validating models...

running with lxml.etree
0 errors found
May 14, 2014 - 09:00:59
Django version 1.6.2, using settings 'settings'
Starting development server at http://0.0.0.0:8000/
Quit the server with CONTROL-C.
Validating models...

running with lxml.etree
0 errors found
May 14, 2014 - 09:02:25
Django version 1.6.2, using settings 'settings'
Starting development server at http://0.0.0.0:8000/
Quit the server with CONTROL-C.
Validating models...

running with lxml.etree
0 errors found
May 14, 2014 - 09:03:44
Django version 1.6.2, using settings 'settings'
Starting development server at http://0.0.0.0:8000/
Quit the server with CONTROL-C.
Validating models...

running with lxml.etree
0 errors found
May 14, 2014 - 09:05:13
Django version 1.6.2, using settings 'settings'
Starting development server at http://0.0.0.0:8000/
Quit the server with CONTROL-C.
Validating models...

running with lxml.etree
0 errors found
May 14, 2014 - 09:06:48
Django version 1.6.2, using settings 'settings'
Starting development server at http://0.0.0.0:8000/
Quit the server with CONTROL-C.
Validating models...

running with lxml.etree
0 errors found
May 14, 2014 - 09:06:53
Django version 1.6.2, using settings 'settings'
Starting development server at http://0.0.0.0:8000/
Quit the server with CONTROL-C.
Validating models...

running with lxml.etree
0 errors found
May 14, 2014 - 09:07:59
Django version 1.6.2, using settings 'settings'
Starting development server at http://0.0.0.0:8000/
Quit the server with CONTROL-C.
Validating models...

running with lxml.etree
0 errors found
May 14, 2014 - 09:08:39
Django version 1.6.2, using settings 'settings'
Starting development server at http://0.0.0.0:8000/
Quit the server with CONTROL-C.
Validating models...

running with lxml.etree
0 errors found
May 14, 2014 - 09:09:52
Django version 1.6.2, using settings 'settings'
Starting development server at http://0.0.0.0:8000/
Quit the server with CONTROL-C.
Validating models...

running with lxml.etree
0 errors found
May 14, 2014 - 09:11:34
Django version 1.6.2, using settings 'settings'
Starting development server at http://0.0.0.0:8000/
Quit the server with CONTROL-C.
Validating models...

running with lxml.etree
0 errors found
May 14, 2014 - 09:18:48
Django version 1.6.2, using settings 'settings'
Starting development server at http://0.0.0.0:8000/
Quit the server with CONTROL-C.
Validating models...

running with lxml.etree
0 errors found
May 14, 2014 - 09:19:17
Django version 1.6.2, using settings 'settings'
Starting development server at http://0.0.0.0:8000/
Quit the server with CONTROL-C.
Validating models...

running with lxml.etree
0 errors found
May 14, 2014 - 09:19:39
Django version 1.6.2, using settings 'settings'
Starting development server at http://0.0.0.0:8000/
Quit the server with CONTROL-C.
Validating models...

running with lxml.etree
0 errors found
May 14, 2014 - 09:19:43
Django version 1.6.2, using settings 'settings'
Starting development server at http://0.0.0.0:8000/
Quit the server with CONTROL-C.
Validating models...

running with lxml.etree
0 errors found
May 14, 2014 - 09:21:35
Django version 1.6.2, using settings 'settings'
Starting development server at http://0.0.0.0:8000/
Quit the server with CONTROL-C.
Validating models...

running with lxml.etree
0 errors found
May 14, 2014 - 09:27:42
Django version 1.6.2, using settings 'settings'
Starting development server at http://0.0.0.0:8000/
Quit the server with CONTROL-C.
Validating models...

running with lxml.etree
0 errors found
May 14, 2014 - 09:28:54
Django version 1.6.2, using settings 'settings'
Starting development server at http://0.0.0.0:8000/
Quit the server with CONTROL-C.
Validating models...

running with lxml.etree
0 errors found
May 14, 2014 - 09:29:37
Django version 1.6.2, using settings 'settings'
Starting development server at http://0.0.0.0:8000/
Quit the server with CONTROL-C.
Validating models...

running with lxml.etree
0 errors found
May 14, 2014 - 09:35:22
Django version 1.6.2, using settings 'settings'
Starting development server at http://0.0.0.0:8000/
Quit the server with CONTROL-C.
Validating models...

running with lxml.etree
0 errors found
May 14, 2014 - 09:38:53
Django version 1.6.2, using settings 'settings'
Starting development server at http://0.0.0.0:8000/
Quit the server with CONTROL-C.
Validating models...

running with lxml.etree
0 errors found
May 14, 2014 - 09:41:08
Django version 1.6.2, using settings 'settings'
Starting development server at http://0.0.0.0:8000/
Quit the server with CONTROL-C.
Validating models...

running with lxml.etree
0 errors found
May 14, 2014 - 09:47:31
Django version 1.6.2, using settings 'settings'
Starting development server at http://0.0.0.0:8000/
Quit the server with CONTROL-C.
Validating models...

running with lxml.etree
0 errors found
May 14, 2014 - 09:49:36
Django version 1.6.2, using settings 'settings'
Starting development server at http://0.0.0.0:8000/
Quit the server with CONTROL-C.
Validating models...

running with lxml.etree
0 errors found
May 14, 2014 - 09:49:44
Django version 1.6.2, using settings 'settings'
Starting development server at http://0.0.0.0:8000/
Quit the server with CONTROL-C.
Unhandled exception in thread started by <function wrapper at 0x1ea4ed8>
Validating models...

Traceback (most recent call last):
  File "/usr/lib/python2.6/site-packages/django/utils/autoreload.py", line 93, in wrapper
    fn(*args, **kwargs)
  File "/usr/lib/python2.6/site-packages/django/core/management/commands/runserver.py", line 101, in inner_run
    self.validate(display_num_errors=True)
  File "/usr/lib/python2.6/site-packages/django/core/management/base.py", line 310, in validate
    num_errors = get_validation_errors(s, app)
  File "/usr/lib/python2.6/site-packages/django/core/management/validation.py", line 34, in get_validation_errors
    for (app_name, error) in get_app_errors().items():
  File "/usr/lib/python2.6/site-packages/django/db/models/loading.py", line 196, in get_app_errors
    self._populate()
  File "/usr/lib/python2.6/site-packages/django/db/models/loading.py", line 75, in _populate
    self.load_app(app_name, True)
  File "/usr/lib/python2.6/site-packages/django/db/models/loading.py", line 99, in load_app
    models = import_module('%s.models' % app_name)
  File "/usr/lib/python2.6/site-packages/django/utils/importlib.py", line 40, in import_module
    __import__(name)
  File "/home/ec2-user/django15/xmlparser/models.py", line 9, in <module>
    from utils.util import load_xml_tree, load_to_csv, retrieve_from_ftp, decompress_gz, get_ftp_file_name, get_file_path
  File "/home/ec2-user/django15/utils/util.py", line 86
    row = [c.encode('utf8') if isinstance(c, unicode) else c for c in row]:#row.encode('utf-8')
                                                                          ^
SyntaxError: invalid syntax
Unhandled exception in thread started by <function wrapper at 0x1dc7ed8>
Validating models...

Traceback (most recent call last):
  File "/usr/lib/python2.6/site-packages/django/utils/autoreload.py", line 93, in wrapper
    fn(*args, **kwargs)
  File "/usr/lib/python2.6/site-packages/django/core/management/commands/runserver.py", line 101, in inner_run
    self.validate(display_num_errors=True)
  File "/usr/lib/python2.6/site-packages/django/core/management/base.py", line 310, in validate
    num_errors = get_validation_errors(s, app)
  File "/usr/lib/python2.6/site-packages/django/core/management/validation.py", line 34, in get_validation_errors
    for (app_name, error) in get_app_errors().items():
  File "/usr/lib/python2.6/site-packages/django/db/models/loading.py", line 196, in get_app_errors
    self._populate()
  File "/usr/lib/python2.6/site-packages/django/db/models/loading.py", line 75, in _populate
    self.load_app(app_name, True)
  File "/usr/lib/python2.6/site-packages/django/db/models/loading.py", line 99, in load_app
    models = import_module('%s.models' % app_name)
  File "/usr/lib/python2.6/site-packages/django/utils/importlib.py", line 40, in import_module
    __import__(name)
  File "/home/ec2-user/django15/xmlparser/models.py", line 9, in <module>
    from utils.util import load_xml_tree, load_to_csv, retrieve_from_ftp, decompress_gz, get_ftp_file_name, get_file_path
  File "/home/ec2-user/django15/utils/util.py", line 86
    row = [c.encode('utf8') if isinstance(c, unicode) else c for c in row]:
                                                                          ^
SyntaxError: invalid syntax
Validating models...

running with lxml.etree
0 errors found
May 14, 2014 - 09:56:23
Django version 1.6.2, using settings 'settings'
Starting development server at http://0.0.0.0:8000/
Quit the server with CONTROL-C.
Validating models...

running with lxml.etree
0 errors found
May 15, 2014 - 00:46:51
Django version 1.6.2, using settings 'settings'
Starting development server at http://0.0.0.0:8000/
Quit the server with CONTROL-C.
Validating models...

running with lxml.etree
0 errors found
May 15, 2014 - 00:51:07
Django version 1.6.2, using settings 'settings'
Starting development server at http://0.0.0.0:8000/
Quit the server with CONTROL-C.
Validating models...

running with lxml.etree
0 errors found
May 15, 2014 - 00:51:33
Django version 1.6.2, using settings 'settings'
Starting development server at http://0.0.0.0:8000/
Quit the server with CONTROL-C.
Validating models...

running with lxml.etree
0 errors found
May 15, 2014 - 00:56:06
Django version 1.6.2, using settings 'settings'
Starting development server at http://0.0.0.0:8000/
Quit the server with CONTROL-C.
Validating models...

running with lxml.etree
0 errors found
May 15, 2014 - 00:56:26
Django version 1.6.2, using settings 'settings'
Starting development server at http://0.0.0.0:8000/
Quit the server with CONTROL-C.
Validating models...

running with lxml.etree
0 errors found
May 15, 2014 - 00:56:57
Django version 1.6.2, using settings 'settings'
Starting development server at http://0.0.0.0:8000/
Quit the server with CONTROL-C.
Validating models...

running with lxml.etree
0 errors found
May 15, 2014 - 00:59:19
Django version 1.6.2, using settings 'settings'
Starting development server at http://0.0.0.0:8000/
Quit the server with CONTROL-C.
Validating models...

running with lxml.etree
0 errors found
May 15, 2014 - 01:00:46
Django version 1.6.2, using settings 'settings'
Starting development server at http://0.0.0.0:8000/
Quit the server with CONTROL-C.
Unhandled exception in thread started by <function wrapper at 0x2651ed8>
Validating models...

Traceback (most recent call last):
  File "/usr/lib/python2.6/site-packages/django/utils/autoreload.py", line 93, in wrapper
    fn(*args, **kwargs)
  File "/usr/lib/python2.6/site-packages/django/core/management/commands/runserver.py", line 101, in inner_run
    self.validate(display_num_errors=True)
  File "/usr/lib/python2.6/site-packages/django/core/management/base.py", line 310, in validate
    num_errors = get_validation_errors(s, app)
  File "/usr/lib/python2.6/site-packages/django/core/management/validation.py", line 34, in get_validation_errors
    for (app_name, error) in get_app_errors().items():
  File "/usr/lib/python2.6/site-packages/django/db/models/loading.py", line 196, in get_app_errors
    self._populate()
  File "/usr/lib/python2.6/site-packages/django/db/models/loading.py", line 75, in _populate
    self.load_app(app_name, True)
  File "/usr/lib/python2.6/site-packages/django/db/models/loading.py", line 99, in load_app
    models = import_module('%s.models' % app_name)
  File "/usr/lib/python2.6/site-packages/django/utils/importlib.py", line 40, in import_module
    __import__(name)
  File "/home/ec2-user/django15/xmlparser/models.py", line 73
    class TheatreMovieManager(models.Manager):
    ^
IndentationError: unexpected unindent
Unhandled exception in thread started by <function wrapper at 0xb5ded8>
Validating models...

Traceback (most recent call last):
  File "/usr/lib/python2.6/site-packages/django/utils/autoreload.py", line 93, in wrapper
    fn(*args, **kwargs)
  File "/usr/lib/python2.6/site-packages/django/core/management/commands/runserver.py", line 101, in inner_run
    self.validate(display_num_errors=True)
  File "/usr/lib/python2.6/site-packages/django/core/management/base.py", line 310, in validate
    num_errors = get_validation_errors(s, app)
  File "/usr/lib/python2.6/site-packages/django/core/management/validation.py", line 34, in get_validation_errors
    for (app_name, error) in get_app_errors().items():
  File "/usr/lib/python2.6/site-packages/django/db/models/loading.py", line 196, in get_app_errors
    self._populate()
  File "/usr/lib/python2.6/site-packages/django/db/models/loading.py", line 75, in _populate
    self.load_app(app_name, True)
  File "/usr/lib/python2.6/site-packages/django/db/models/loading.py", line 99, in load_app
    models = import_module('%s.models' % app_name)
  File "/usr/lib/python2.6/site-packages/django/utils/importlib.py", line 40, in import_module
    __import__(name)
  File "/home/ec2-user/django15/xmlparser/models.py", line 76
    class TheatreMovieManager(models.Manager):
    ^
IndentationError: unexpected unindent
Validating models...

running with lxml.etree
0 errors found
May 15, 2014 - 01:02:16
Django version 1.6.2, using settings 'settings'
Starting development server at http://0.0.0.0:8000/
Quit the server with CONTROL-C.
Validating models...

running with lxml.etree
0 errors found
May 15, 2014 - 01:02:21
Django version 1.6.2, using settings 'settings'
Starting development server at http://0.0.0.0:8000/
Quit the server with CONTROL-C.
Validating models...

running with lxml.etree
0 errors found
May 15, 2014 - 01:03:00
Django version 1.6.2, using settings 'settings'
Starting development server at http://0.0.0.0:8000/
Quit the server with CONTROL-C.
Validating models...

running with lxml.etree
0 errors found
May 15, 2014 - 01:03:09
Django version 1.6.2, using settings 'settings'
Starting development server at http://0.0.0.0:8000/
Quit the server with CONTROL-C.
Validating models...

running with lxml.etree
0 errors found
May 15, 2014 - 01:04:15
Django version 1.6.2, using settings 'settings'
Starting development server at http://0.0.0.0:8000/
Quit the server with CONTROL-C.
Unhandled exception in thread started by <function wrapper at 0x1c01ed8>
Traceback (most recent call last):
  File "/usr/lib/python2.6/site-packages/django/utils/autoreload.py", line 100, in wrapper
    filename = traceback.extract_tb(tb)[-1][0]
TypeError: 'NoneType' object is not callable
Validating models...

running with lxml.etree
0 errors found
May 15, 2014 - 01:12:04
Django version 1.6.2, using settings 'settings'
Starting development server at http://0.0.0.0:8000/
Quit the server with CONTROL-C.
Validating models...

running with lxml.etree
0 errors found
May 15, 2014 - 01:14:46
Django version 1.6.2, using settings 'settings'
Starting development server at http://0.0.0.0:8000/
Quit the server with CONTROL-C.
Validating models...

running with lxml.etree
0 errors found
May 15, 2014 - 01:16:50
Django version 1.6.2, using settings 'settings'
Starting development server at http://0.0.0.0:8000/
Quit the server with CONTROL-C.
Validating models...

running with lxml.etree
0 errors found
May 15, 2014 - 01:17:55
Django version 1.6.2, using settings 'settings'
Starting development server at http://0.0.0.0:8000/
Quit the server with CONTROL-C.
Unhandled exception in thread started by <function wrapper at 0xc46ed8>
Traceback (most recent call last):
  File "/usr/lib/python2.6/site-packages/django/utils/autoreload.py", line 100, in wrapper
    filename = traceback.extract_tb(tb)[-1][0]
TypeError: 'NoneType' object is not callable
Validating models...

running with lxml.etree
0 errors found
May 15, 2014 - 01:18:45
Django version 1.6.2, using settings 'settings'
Starting development server at http://0.0.0.0:8000/
Quit the server with CONTROL-C.
Validating models...

running with lxml.etree
0 errors found
May 15, 2014 - 01:19:05
Django version 1.6.2, using settings 'settings'
Starting development server at http://0.0.0.0:8000/
Quit the server with CONTROL-C.
[15/May/2014 15:56:25] "GET / HTTP/1.1" 404 2139
[15/May/2014 15:56:30] "GET /api/theatres/all/ HTTP/1.1" 200 3859
[15/May/2014 16:00:12] "GET /api/theatres/test/ HTTP/1.1" 404 2193
[15/May/2014 16:01:13] "GET /api/test_showtimes/ HTTP/1.1" 404 2196
No handlers could be found for logger "xmlparser.views"
[15/May/2014 16:01:18] "GET /api/test_showtime/ HTTP/1.1" 200 1343
[16/May/2014 02:05:12] "GET /api/theatres/all/ HTTP/1.1" 200 3859
[16/May/2014 02:07:41] "GET /api/theatres/all/ HTTP/1.1" 200 3859
Validating models...

running with lxml.etree
0 errors found
May 15, 2014 - 01:19:16
Django version 1.6.2, using settings 'settings'
Starting development server at http://0.0.0.0:8000/
Quit the server with CONTROL-C.
lat : None
lon : None
No handlers could be found for logger "xmlparser.views"
[16/May/2014 02:10:53] "GET /api/test_showtime/ HTTP/1.1" 500 81544
[16/May/2014 02:11:20] "GET /api/test_showtime/?lat=30 HTTP/1.1" 200 15
[16/May/2014 02:11:29] "GET /api/test_showtime/?lat=30.4704 HTTP/1.1" 500 126782
Validating models...

running with lxml.etree
0 errors found
May 16, 2014 - 02:10:42
Django version 1.6.2, using settings 'settings'
Starting development server at http://0.0.0.0:8000/
Quit the server with CONTROL-C.
lat : None
lon : None
lat : 30
lon : None
lat : 30.4704
lon : None
No handlers could be found for logger "xmlparser.views"
[16/May/2014 02:13:26] "GET /api/test_showtime/?lat=30.4704 HTTP/1.1" 500 126957
Validating models...

running with lxml.etree
0 errors found
May 16, 2014 - 02:13:24
Django version 1.6.2, using settings 'settings'
Starting development server at http://0.0.0.0:8000/
Quit the server with CONTROL-C.
lat : 30.4704
lon : None
No handlers could be found for logger "xmlparser.views"
[16/May/2014 02:14:13] "GET /api/test_showtime/?lat=30.4704 HTTP/1.1" 200 46
Validating models...

running with lxml.etree
0 errors found
May 16, 2014 - 02:13:49
Django version 1.6.2, using settings 'settings'
Starting development server at http://0.0.0.0:8000/
Quit the server with CONTROL-C.
lat : 30.4704
lon : None
[16/May/2014 16:18:23] "GET /api/test_showtime/?lat=30.4704 HTTP/1.1" 500 75439
No handlers could be found for logger "xmlparser.views"
[16/May/2014 16:19:36] "GET /api/test_showtime/?lat=30.4704 HTTP/1.1" 200 46
GEOS_ERROR: ParseException: Expected number but encountered ','

[16/May/2014 16:19:59] "GET /api/theatres/nearby/?lat=30.4704&lon=-97.5000 HTTP/1.1" 500 82615
GEOS_ERROR: ParseException: Expected number but encountered ','

[16/May/2014 16:20:36] "GET /api/theatres/nearby/?lat=30.4704&lon=-97.5000&range=10 HTTP/1.1" 500 82887
Validating models...

running with lxml.etree
0 errors found
May 16, 2014 - 16:14:33
Django version 1.6.2, using settings 'settings'
Starting development server at http://0.0.0.0:8000/
Quit the server with CONTROL-C.
lat : 30.4704
lon : None
[16/May/2014 16:23:54] "GET /api/theatres/nearby/?lat=30.4704&lon=-97.5000&range=10 HTTP/1.1" 500 98255
[16/May/2014 16:24:08] "GET /api/theatres/nearby/?lat=30.4704&lon=-97.5000&range=10 HTTP/1.1" 500 98255
Validating models...

running with lxml.etree
0 errors found
May 16, 2014 - 16:23:53
Django version 1.6.2, using settings 'settings'
Starting development server at http://0.0.0.0:8000/
Quit the server with CONTROL-C.
[16/May/2014 16:31:01] "GET /api/theatres/nearby/?lat=30.4704&lon=-97.5000&range=10 HTTP/1.1" 500 75956
[16/May/2014 16:32:39] "GET /api/theatres/nearby/?lat=30.4704&lon=-97.5000&range=10 HTTP/1.1" 500 75494
[16/May/2014 16:33:39] "GET /api/theatres/nearby/?lat=30.4704&lon=-97.5000&range=10 HTTP/1.1" 500 75735
[16/May/2014 16:33:53] "GET /api/theatres/nearby/?lat=30.4704&lon=-97.5000&range=10 HTTP/1.1" 500 75434
[16/May/2014 16:34:32] "GET /api/theatres/nearby/?lat=30.4704&lon=-97.5000&range=10 HTTP/1.1" 500 67758
Validating models...

running with lxml.etree
0 errors found
May 16, 2014 - 16:30:59
Django version 1.6.2, using settings 'settings'
Starting development server at http://0.0.0.0:8000/
Quit the server with CONTROL-C.
[16/May/2014 16:40:10] "GET /api/theatres/nearby/?lat=30.4704&lon=-97.5000&range=10 HTTP/1.1" 500 67588
Validating models...

running with lxml.etree
0 errors found
May 16, 2014 - 16:40:09
Django version 1.6.2, using settings 'settings'
Starting development server at http://0.0.0.0:8000/
Quit the server with CONTROL-C.
[16/May/2014 16:40:21] "GET /api/theatres/nearby/?lat=30.4704&lon=-97.5000&range=10 HTTP/1.1" 200 88
Validating models...

running with lxml.etree
0 errors found
May 16, 2014 - 16:40:21
Django version 1.6.2, using settings 'settings'
Starting development server at http://0.0.0.0:8000/
Quit the server with CONTROL-C.
[16/May/2014 16:40:50] "GET /api/theatres/nearby/?lat=30.4704&lon=-97.5000&range=10 HTTP/1.1" 500 122957
Validating models...

running with lxml.etree
0 errors found
May 16, 2014 - 16:40:47
Django version 1.6.2, using settings 'settings'
Starting development server at http://0.0.0.0:8000/
Quit the server with CONTROL-C.
[16/May/2014 16:41:07] "GET /api/theatres/nearby/?lat=30.4704&lon=-97.5000&range=10 HTTP/1.1" 200 212
Validating models...

running with lxml.etree
0 errors found
May 16, 2014 - 16:41:06
Django version 1.6.2, using settings 'settings'
Starting development server at http://0.0.0.0:8000/
Quit the server with CONTROL-C.
[16/May/2014 16:42:14] "GET /api/theatres/nearby/?lat=30.4704&lon=-97.5000&range=10 HTTP/1.1" 200 610
[16/May/2014 16:42:16] "GET /api/theatres/nearby/?lat=30.4704&lon=-97.5000&range=10 HTTP/1.1" 200 610
Validating models...

running with lxml.etree
0 errors found
May 16, 2014 - 16:42:11
Django version 1.6.2, using settings 'settings'
Starting development server at http://0.0.0.0:8000/
Quit the server with CONTROL-C.
[16/May/2014 16:45:13] "GET /api/theatres/nearby/?lat=30.4704&lon=-97.5000&range=10 HTTP/1.1" 200 602
Validating models...

running with lxml.etree
0 errors found
May 16, 2014 - 16:45:13
Django version 1.6.2, using settings 'settings'
Starting development server at http://0.0.0.0:8000/
Quit the server with CONTROL-C.
[16/May/2014 16:45:35] "GET /api/theatres/nearby/?lat=30.4704&lon=-97.5000&range=10 HTTP/1.1" 200 610
Validating models...

running with lxml.etree
0 errors found
May 16, 2014 - 16:45:34
Django version 1.6.2, using settings 'settings'
Starting development server at http://0.0.0.0:8000/
Quit the server with CONTROL-C.
[16/May/2014 16:46:16] "GET /api/theatres/nearby/?lat=30.4704&lon=-97.8038&range=10 HTTP/1.1" 200 2099
Validating models...

running with lxml.etree
0 errors found
May 16, 2014 - 16:45:43
Django version 1.6.2, using settings 'settings'
Starting development server at http://0.0.0.0:8000/
Quit the server with CONTROL-C.
Validating models...

running with lxml.etree
0 errors found
May 16, 2014 - 16:59:25
Django version 1.6.2, using settings 'settings'
Starting development server at http://0.0.0.0:8000/
Quit the server with CONTROL-C.
Validating models...

running with lxml.etree
0 errors found
May 17, 2014 - 01:40:00
Django version 1.6.2, using settings 'settings'
Starting development server at http://0.0.0.0:8000/
Quit the server with CONTROL-C.
Validating models...

running with lxml.etree
0 errors found
May 17, 2014 - 01:40:26
Django version 1.6.2, using settings 'settings'
Starting development server at http://0.0.0.0:8000/
Quit the server with CONTROL-C.
Unhandled exception in thread started by <function wrapper at 0x10ebed8>
Validating models...

running with lxml.etree
Traceback (most recent call last):
  File "/usr/lib/python2.6/site-packages/django/utils/autoreload.py", line 93, in wrapper
    fn(*args, **kwargs)
  File "/usr/lib/python2.6/site-packages/django/core/management/commands/runserver.py", line 101, in inner_run
    self.validate(display_num_errors=True)
  File "/usr/lib/python2.6/site-packages/django/core/management/base.py", line 314, in validate
    raise CommandError("One or more models did not validate:\n%s" % error_text)
django.core.management.base.CommandError: One or more models did not validate:
xmlparser.theatremovie: "index_together" refers to date, a field that doesn't exist.

Validating models...

running with lxml.etree
0 errors found
May 17, 2014 - 01:41:25
Django version 1.6.2, using settings 'settings'
Starting development server at http://0.0.0.0:8000/
Quit the server with CONTROL-C.
Unhandled exception in thread started by <function wrapper at 0x1ec1ed8>
Traceback (most recent call last):
  File "/usr/lib/python2.6/site-packages/django/utils/autoreload.py", line 100, in wrapper
    filename = traceback.extract_tb(tb)[-1][0]
TypeError: 'NoneType' object is not callable
Validating models...

running with lxml.etree
0 errors found
May 17, 2014 - 01:41:37
Django version 1.6.2, using settings 'settings'
Starting development server at http://0.0.0.0:8000/
Quit the server with CONTROL-C.
Validating models...

running with lxml.etree
0 errors found
May 17, 2014 - 01:41:43
Django version 1.6.2, using settings 'settings'
Starting development server at http://0.0.0.0:8000/
Quit the server with CONTROL-C.
Unhandled exception in thread started by <function wrapper at 0xc10ed8>
Traceback (most recent call last):
  File "/usr/lib/python2.6/site-packages/django/utils/autoreload.py", line 100, in wrapper
    filename = traceback.extract_tb(tb)[-1][0]
TypeError: 'NoneType' object is not callable
Validating models...

running with lxml.etree
0 errors found
May 17, 2014 - 01:43:27
Django version 1.6.2, using settings 'settings'
Starting development server at http://0.0.0.0:8000/
Quit the server with CONTROL-C.
Validating models...

running with lxml.etree
0 errors found
May 17, 2014 - 01:43:37
Django version 1.6.2, using settings 'settings'
Starting development server at http://0.0.0.0:8000/
Quit the server with CONTROL-C.
Unhandled exception in thread started by <function wrapper at 0xd56ed8>
Validating models...

Traceback (most recent call last):
  File "/usr/lib/python2.6/site-packages/django/utils/autoreload.py", line 93, in wrapper
    fn(*args, **kwargs)
  File "/usr/lib/python2.6/site-packages/django/core/management/commands/runserver.py", line 101, in inner_run
    self.validate(display_num_errors=True)
  File "/usr/lib/python2.6/site-packages/django/core/management/base.py", line 310, in validate
    num_errors = get_validation_errors(s, app)
  File "/usr/lib/python2.6/site-packages/django/core/management/validation.py", line 34, in get_validation_errors
    for (app_name, error) in get_app_errors().items():
  File "/usr/lib/python2.6/site-packages/django/db/models/loading.py", line 196, in get_app_errors
    self._populate()
  File "/usr/lib/python2.6/site-packages/django/db/models/loading.py", line 75, in _populate
    self.load_app(app_name, True)
  File "/usr/lib/python2.6/site-packages/django/db/models/loading.py", line 99, in load_app
    models = import_module('%s.models' % app_name)
  File "/usr/lib/python2.6/site-packages/django/utils/importlib.py", line 40, in import_module
    __import__(name)
  File "/home/ec2-user/django15/xmlparser/models.py", line 105
    sline.append(t.findtext('.')))
                                 ^
SyntaxError: invalid syntax
Unhandled exception in thread started by <function wrapper at 0x238ded8>
Validating models...

Traceback (most recent call last):
  File "/usr/lib/python2.6/site-packages/django/utils/autoreload.py", line 93, in wrapper
    fn(*args, **kwargs)
  File "/usr/lib/python2.6/site-packages/django/core/management/commands/runserver.py", line 101, in inner_run
    self.validate(display_num_errors=True)
  File "/usr/lib/python2.6/site-packages/django/core/management/base.py", line 310, in validate
    num_errors = get_validation_errors(s, app)
  File "/usr/lib/python2.6/site-packages/django/core/management/validation.py", line 34, in get_validation_errors
    for (app_name, error) in get_app_errors().items():
  File "/usr/lib/python2.6/site-packages/django/db/models/loading.py", line 196, in get_app_errors
    self._populate()
  File "/usr/lib/python2.6/site-packages/django/db/models/loading.py", line 75, in _populate
    self.load_app(app_name, True)
  File "/usr/lib/python2.6/site-packages/django/db/models/loading.py", line 99, in load_app
    models = import_module('%s.models' % app_name)
  File "/usr/lib/python2.6/site-packages/django/utils/importlib.py", line 40, in import_module
    __import__(name)
  File "/home/ec2-user/django15/xmlparser/models.py", line 105
    sline.append(t.findtext('.')))
                                 ^
SyntaxError: invalid syntax
Unhandled exception in thread started by <function wrapper at 0x956ed8>
Validating models...

Traceback (most recent call last):
  File "/usr/lib/python2.6/site-packages/django/utils/autoreload.py", line 93, in wrapper
    fn(*args, **kwargs)
  File "/usr/lib/python2.6/site-packages/django/core/management/commands/runserver.py", line 101, in inner_run
    self.validate(display_num_errors=True)
  File "/usr/lib/python2.6/site-packages/django/core/management/base.py", line 310, in validate
    num_errors = get_validation_errors(s, app)
  File "/usr/lib/python2.6/site-packages/django/core/management/validation.py", line 34, in get_validation_errors
    for (app_name, error) in get_app_errors().items():
  File "/usr/lib/python2.6/site-packages/django/db/models/loading.py", line 196, in get_app_errors
    self._populate()
  File "/usr/lib/python2.6/site-packages/django/db/models/loading.py", line 75, in _populate
    self.load_app(app_name, True)
  File "/usr/lib/python2.6/site-packages/django/db/models/loading.py", line 99, in load_app
    models = import_module('%s.models' % app_name)
  File "/usr/lib/python2.6/site-packages/django/utils/importlib.py", line 40, in import_module
    __import__(name)
  File "/home/ec2-user/django15/xmlparser/models.py", line 105
    sline.append(t.findtext('.')))
                                 ^
SyntaxError: invalid syntax
Unhandled exception in thread started by <function wrapper at 0x22d8ed8>
Validating models...

Traceback (most recent call last):
  File "/usr/lib/python2.6/site-packages/django/utils/autoreload.py", line 93, in wrapper
    fn(*args, **kwargs)
  File "/usr/lib/python2.6/site-packages/django/core/management/commands/runserver.py", line 101, in inner_run
    self.validate(display_num_errors=True)
  File "/usr/lib/python2.6/site-packages/django/core/management/base.py", line 310, in validate
    num_errors = get_validation_errors(s, app)
  File "/usr/lib/python2.6/site-packages/django/core/management/validation.py", line 34, in get_validation_errors
    for (app_name, error) in get_app_errors().items():
  File "/usr/lib/python2.6/site-packages/django/db/models/loading.py", line 196, in get_app_errors
    self._populate()
  File "/usr/lib/python2.6/site-packages/django/db/models/loading.py", line 75, in _populate
    self.load_app(app_name, True)
  File "/usr/lib/python2.6/site-packages/django/db/models/loading.py", line 99, in load_app
    models = import_module('%s.models' % app_name)
  File "/usr/lib/python2.6/site-packages/django/utils/importlib.py", line 40, in import_module
    __import__(name)
  File "/home/ec2-user/django15/xmlparser/models.py", line 105
    sline.append(t.findtext('.')))
                                 ^
SyntaxError: invalid syntax
Unhandled exception in thread started by <function wrapper at 0x22c2ed8>
Validating models...

Traceback (most recent call last):
  File "/usr/lib/python2.6/site-packages/django/utils/autoreload.py", line 93, in wrapper
    fn(*args, **kwargs)
  File "/usr/lib/python2.6/site-packages/django/core/management/commands/runserver.py", line 101, in inner_run
    self.validate(display_num_errors=True)
  File "/usr/lib/python2.6/site-packages/django/core/management/base.py", line 310, in validate
    num_errors = get_validation_errors(s, app)
  File "/usr/lib/python2.6/site-packages/django/core/management/validation.py", line 34, in get_validation_errors
    for (app_name, error) in get_app_errors().items():
  File "/usr/lib/python2.6/site-packages/django/db/models/loading.py", line 196, in get_app_errors
    self._populate()
  File "/usr/lib/python2.6/site-packages/django/db/models/loading.py", line 75, in _populate
    self.load_app(app_name, True)
  File "/usr/lib/python2.6/site-packages/django/db/models/loading.py", line 99, in load_app
    models = import_module('%s.models' % app_name)
  File "/usr/lib/python2.6/site-packages/django/utils/importlib.py", line 40, in import_module
    __import__(name)
  File "/home/ec2-user/django15/xmlparser/models.py", line 105
    sline.append(t.findtext('.')))
                                 ^
SyntaxError: invalid syntax
Unhandled exception in thread started by <function wrapper at 0x229ded8>
Validating models...

Traceback (most recent call last):
  File "/usr/lib/python2.6/site-packages/django/utils/autoreload.py", line 93, in wrapper
    fn(*args, **kwargs)
  File "/usr/lib/python2.6/site-packages/django/core/management/commands/runserver.py", line 101, in inner_run
    self.validate(display_num_errors=True)
  File "/usr/lib/python2.6/site-packages/django/core/management/base.py", line 310, in validate
    num_errors = get_validation_errors(s, app)
  File "/usr/lib/python2.6/site-packages/django/core/management/validation.py", line 34, in get_validation_errors
    for (app_name, error) in get_app_errors().items():
  File "/usr/lib/python2.6/site-packages/django/db/models/loading.py", line 196, in get_app_errors
    self._populate()
  File "/usr/lib/python2.6/site-packages/django/db/models/loading.py", line 75, in _populate
    self.load_app(app_name, True)
  File "/usr/lib/python2.6/site-packages/django/db/models/loading.py", line 99, in load_app
    models = import_module('%s.models' % app_name)
  File "/usr/lib/python2.6/site-packages/django/utils/importlib.py", line 40, in import_module
    __import__(name)
  File "/home/ec2-user/django15/xmlparser/models.py", line 105
    sline.append(t.findtext('.')))
                                 ^
SyntaxError: invalid syntax
Unhandled exception in thread started by <function wrapper at 0x121fed8>
Validating models...

Traceback (most recent call last):
  File "/usr/lib/python2.6/site-packages/django/utils/autoreload.py", line 93, in wrapper
    fn(*args, **kwargs)
  File "/usr/lib/python2.6/site-packages/django/core/management/commands/runserver.py", line 101, in inner_run
    self.validate(display_num_errors=True)
  File "/usr/lib/python2.6/site-packages/django/core/management/base.py", line 310, in validate
    num_errors = get_validation_errors(s, app)
  File "/usr/lib/python2.6/site-packages/django/core/management/validation.py", line 34, in get_validation_errors
    for (app_name, error) in get_app_errors().items():
  File "/usr/lib/python2.6/site-packages/django/db/models/loading.py", line 196, in get_app_errors
    self._populate()
  File "/usr/lib/python2.6/site-packages/django/db/models/loading.py", line 75, in _populate
    self.load_app(app_name, True)
  File "/usr/lib/python2.6/site-packages/django/db/models/loading.py", line 99, in load_app
    models = import_module('%s.models' % app_name)
  File "/usr/lib/python2.6/site-packages/django/utils/importlib.py", line 40, in import_module
    __import__(name)
  File "/home/ec2-user/django15/xmlparser/models.py", line 105
    sline.append(t.findtext('.')))
                                 ^
SyntaxError: invalid syntax
Unhandled exception in thread started by <function wrapper at 0x13bced8>
Validating models...

Traceback (most recent call last):
  File "/usr/lib/python2.6/site-packages/django/utils/autoreload.py", line 93, in wrapper
    fn(*args, **kwargs)
  File "/usr/lib/python2.6/site-packages/django/core/management/commands/runserver.py", line 101, in inner_run
    self.validate(display_num_errors=True)
  File "/usr/lib/python2.6/site-packages/django/core/management/base.py", line 310, in validate
    num_errors = get_validation_errors(s, app)
  File "/usr/lib/python2.6/site-packages/django/core/management/validation.py", line 34, in get_validation_errors
    for (app_name, error) in get_app_errors().items():
  File "/usr/lib/python2.6/site-packages/django/db/models/loading.py", line 196, in get_app_errors
    self._populate()
  File "/usr/lib/python2.6/site-packages/django/db/models/loading.py", line 75, in _populate
    self.load_app(app_name, True)
  File "/usr/lib/python2.6/site-packages/django/db/models/loading.py", line 99, in load_app
    models = import_module('%s.models' % app_name)
  File "/usr/lib/python2.6/site-packages/django/utils/importlib.py", line 40, in import_module
    __import__(name)
  File "/home/ec2-user/django15/xmlparser/models.py", line 105
    sline.append(t.findtext('.')))
                                 ^
SyntaxError: invalid syntax
Validating models...

running with lxml.etree
0 errors found
May 17, 2014 - 02:31:12
Django version 1.6.2, using settings 'settings'
Starting development server at http://0.0.0.0:8000/
Quit the server with CONTROL-C.
Validating models...

running with lxml.etree
0 errors found
May 17, 2014 - 02:32:07
Django version 1.6.2, using settings 'settings'
Starting development server at http://0.0.0.0:8000/
Quit the server with CONTROL-C.
Validating models...

running with lxml.etree
0 errors found
May 17, 2014 - 02:44:23
Django version 1.6.2, using settings 'settings'
Starting development server at http://0.0.0.0:8000/
Quit the server with CONTROL-C.
[17/May/2014 17:16:26] "GET /api/theatres/nearby/?lat=30.4704&lon=-97.8038&range=10 HTTP/1.1" 200 2099
[17/May/2014 17:16:37] "GET /api/theatres/nearby/?lat=30.4704&lon=-97.8038&range=15 HTTP/1.1" 200 3767
Validating models...

running with lxml.etree
0 errors found
May 17, 2014 - 03:19:36
Django version 1.6.2, using settings 'settings'
Starting development server at http://0.0.0.0:8000/
Quit the server with CONTROL-C.
[17/May/2014 17:42:08] "GET /api/showtimes/nearby/?lat=30.4704&lon=-97.8038&range=15 HTTP/1.1" 500 75664
[17/May/2014 17:42:44] "GET /api/showtimes/nearby/?lat=30.4704&lon=-97.8038&range=15 HTTP/1.1" 500 75400
[17/May/2014 17:47:34] "GET /api/showtimes/nearby/?lat=30.4704&lon=-97.8038&range=15 HTTP/1.1" 500 119737
Validating models...

running with lxml.etree
0 errors found
May 17, 2014 - 17:35:54
Django version 1.6.2, using settings 'settings'
Starting development server at http://0.0.0.0:8000/
Quit the server with CONTROL-C.
[17/May/2014 17:49:44] "GET /api/showtimes/nearby/?lat=30.4704&lon=-97.8038&range=15 HTTP/1.1" 500 1790620
Validating models...

running with lxml.etree
0 errors found
May 17, 2014 - 17:49:41
Django version 1.6.2, using settings 'settings'
Starting development server at http://0.0.0.0:8000/
Quit the server with CONTROL-C.
Unhandled exception in thread started by <function wrapper at 0xd61ed8>
Traceback (most recent call last):
  File "/usr/lib/python2.6/site-packages/django/utils/autoreload.py", line 100, in wrapper
    filename = traceback.extract_tb(tb)[-1][0]
TypeError: 'NoneType' object is not callable
[17/May/2014 17:50:18] "GET /api/showtimes/nearby/?lat=30.4704&lon=-97.8038&range=15 HTTP/1.1" 200 20637
[17/May/2014 17:50:25] "GET /api/showtimes/nearby/?lat=30.4704&lon=-97.8038&range=5 HTTP/1.1" 200 4540
Validating models...

running with lxml.etree
0 errors found
May 17, 2014 - 17:50:18
Django version 1.6.2, using settings 'settings'
Starting development server at http://0.0.0.0:8000/
Quit the server with CONTROL-C.
[17/May/2014 17:51:21] "GET /api/showtimes/nearby/?lat=30.4704&lon=-97.8038&range=5 HTTP/1.1" 500 474546
Validating models...

running with lxml.etree
0 errors found
May 17, 2014 - 17:50:34
Django version 1.6.2, using settings 'settings'
Starting development server at http://0.0.0.0:8000/
Quit the server with CONTROL-C.
[17/May/2014 17:51:35] "GET /api/showtimes/nearby/?lat=30.4704&lon=-97.8038&range=5 HTTP/1.1" 200 4311
Validating models...

running with lxml.etree
0 errors found
May 17, 2014 - 17:51:33
Django version 1.6.2, using settings 'settings'
Starting development server at http://0.0.0.0:8000/
Quit the server with CONTROL-C.
[17/May/2014 17:53:18] "GET /api/showtimes/nearby/?lat=30.4704&lon=-97.8038&range=5 HTTP/1.1" 500 474696
Validating models...

running with lxml.etree
0 errors found
May 17, 2014 - 17:51:45
Django version 1.6.2, using settings 'settings'
Starting development server at http://0.0.0.0:8000/
Quit the server with CONTROL-C.
[17/May/2014 17:53:46] "GET /api/showtimes/nearby/?lat=30.4704&lon=-97.8038&range=5 HTTP/1.1" 200 5712
Validating models...

running with lxml.etree
0 errors found
May 17, 2014 - 17:53:44
Django version 1.6.2, using settings 'settings'
Starting development server at http://0.0.0.0:8000/
Quit the server with CONTROL-C.
[17/May/2014 18:00:55] "GET /api/showtimes/nearby/?lat=30.4704&lon=-97.8038&range=5 HTTP/1.1" 200 5760
[17/May/2014 18:28:41] "GET /api/showtimes/nearby/?lat=30.4704&lon=-97.8038&range=5 HTTP/1.1" 200 5861
[17/May/2014 18:28:56] "GET /api/showtimes/nearby/?lat=30.4704&lon=-97.8038&range=5 HTTP/1.1" 200 5861
[17/May/2014 18:29:18] "GET /api/showtimes/nearby/?lat=30.4704&lon=-97.8038&range=5 HTTP/1.1" 200 5861
[17/May/2014 18:29:24] "GET /api/showtimes/nearby/?lat=30.4704&lon=-97.8038&range=5 HTTP/1.1" 200 5861
[23/May/2014 01:32:59] "GET /api/theatres/all/ HTTP/1.1" 200 3859
Validating models...

running with lxml.etree
0 errors found
May 17, 2014 - 18:00:54
Django version 1.6.2, using settings 'settings'
Starting development server at http://0.0.0.0:8000/
Quit the server with CONTROL-C.
[23/May/2014 01:35:16] "GET /api/whatever/ HTTP/1.1" 500 80888
[23/May/2014 01:35:37] "GET /api/whatever/ HTTP/1.1" 500 81293
[23/May/2014 01:35:46] "GET /api/whatever/ HTTP/1.1" 200 69
Validating models...

running with lxml.etree
0 errors found
May 23, 2014 - 01:34:18
Django version 1.6.2, using settings 'settings'
Starting development server at http://0.0.0.0:8000/
Quit the server with CONTROL-C.
[23/May/2014 01:35:57] "GET /api/whatever?format=json HTTP/1.1" 301 0
[23/May/2014 01:35:57] "GET /api/whatever/?format=json HTTP/1.1" 200 101
Validating models...

running with lxml.etree
0 errors found
May 23, 2014 - 01:35:48
Django version 1.6.2, using settings 'settings'
Starting development server at http://0.0.0.0:8000/
Quit the server with CONTROL-C.
[23/May/2014 01:42:49] "GET /api/test/?format=json HTTP/1.1" 500 81383
[23/May/2014 01:43:06] "GET /api/test/?format=json HTTP/1.1" 404 4477
Validating models...

running with lxml.etree
0 errors found
May 23, 2014 - 01:41:07
Django version 1.6.2, using settings 'settings'
Starting development server at http://0.0.0.0:8000/
Quit the server with CONTROL-C.
[23/May/2014 01:44:10] "GET /api/test/?format=json HTTP/1.1" 500 66326
[23/May/2014 01:44:44] "GET /api/test/?format=json HTTP/1.1" 500 1003
Validating models...

running with lxml.etree
0 errors found
May 23, 2014 - 01:43:54
Django version 1.6.2, using settings 'settings'
Starting development server at http://0.0.0.0:8000/
Quit the server with CONTROL-C.
[23/May/2014 01:45:14] "GET /api/test/?format=json HTTP/1.1" 500 1149
Validating models...

running with lxml.etree
0 errors found
May 23, 2014 - 01:45:13
Django version 1.6.2, using settings 'settings'
Starting development server at http://0.0.0.0:8000/
Quit the server with CONTROL-C.
[23/May/2014 01:45:36] "GET /api/test/?format=json HTTP/1.1" 200 26062
Validating models...

running with lxml.etree
0 errors found
May 23, 2014 - 01:45:31
Django version 1.6.2, using settings 'settings'
Starting development server at http://0.0.0.0:8000/
Quit the server with CONTROL-C.
[23/May/2014 04:13:18] "GET /api/test/?format=json HTTP/1.1" 200 26782
[23/May/2014 04:13:23] "GET /api/test/?format=json HTTP/1.1" 200 26782
Validating models...

running with lxml.etree
0 errors found
May 23, 2014 - 04:13:15
Django version 1.6.2, using settings 'settings'
Starting development server at http://0.0.0.0:8000/
Quit the server with CONTROL-C.
[23/May/2014 04:13:31] "GET /api/test/?format=json HTTP/1.1" 500 969
Validating models...

running with lxml.etree
0 errors found
May 23, 2014 - 04:13:29
Django version 1.6.2, using settings 'settings'
Starting development server at http://0.0.0.0:8000/
Quit the server with CONTROL-C.
[23/May/2014 04:13:41] "GET /api/test/?format=json HTTP/1.1" 200 26782
Validating models...

running with lxml.etree
0 errors found
May 23, 2014 - 04:13:38
Django version 1.6.2, using settings 'settings'
Starting development server at http://0.0.0.0:8000/
Quit the server with CONTROL-C.
Unhandled exception in thread started by <function wrapper at 0x20f0ed8>
Traceback (most recent call last):
  File "/usr/lib/python2.6/site-packages/django/utils/autoreload.py", line 93, in wrapper
    fn(*args, **kwargs)
  File "/usr/lib/python2.6/site-packages/django/core/management/commands/runserver.py", line 127, in inner_run
    ipv6=self.use_ipv6, threading=threading)
  File "/usr/lib/python2.6/site-packages/django/core/servers/basehttp.py", line 169, in run
    httpd.serve_forever()
  File "/usr/lib64/python2.6/SocketServer.py", line 224, in serve_forever
    r, w, e = select.select([self], [], [], poll_interval)
AttributeError: 'NoneType' object has no attribute 'select'
[23/May/2014 04:14:04] "GET /api/test/?format=json HTTP/1.1" 200 26782
[23/May/2014 04:14:39] "GET /api/test/?format=xml HTTP/1.1" 200 67692
Validating models...

running with lxml.etree
0 errors found
May 23, 2014 - 04:14:03
Django version 1.6.2, using settings 'settings'
Starting development server at http://0.0.0.0:8000/
Quit the server with CONTROL-C.
[23/May/2014 04:21:40] "GET /api/test/?format=xml HTTP/1.1" 200 67692
[23/May/2014 04:23:14] "GET /api/test HTTP/1.1" 301 0
[23/May/2014 04:24:53] "GET /api/test?format=json HTTP/1.1" 301 0
[23/May/2014 04:28:10] "GET /api/v1/test/?format=xml HTTP/1.1" 200 67692
Validating models...

running with lxml.etree
0 errors found
May 23, 2014 - 04:21:28
Django version 1.6.2, using settings 'settings'
Starting development server at http://0.0.0.0:8000/
Quit the server with CONTROL-C.
Unhandled exception in thread started by <function wrapper at 0x1d9fed8>
Traceback (most recent call last):
  File "/usr/lib/python2.6/site-packages/django/utils/autoreload.py", line 96, in wrapper
    et, ev, tb = sys.exc_info()
AttributeError: 'NoneType' object has no attribute 'exc_info'
[23/May/2014 04:28:41] "GET /api/v1/test/?format=xml HTTP/1.1" 200 67692
Validating models...

running with lxml.etree
0 errors found
May 23, 2014 - 04:28:40
Django version 1.6.2, using settings 'settings'
Starting development server at http://0.0.0.0:8000/
Quit the server with CONTROL-C.
[23/May/2014 04:43:38] "GET /api/v1/test/?format=xml HTTP/1.1" 200 67692
[25/May/2014 20:21:57] "GET /api/v1/test/?format=xml HTTP/1.1" 200 67692
[25/May/2014 20:22:04] "GET /api/v1/test/?format=json HTTP/1.1" 200 26782
Validating models...

running with lxml.etree
0 errors found
May 23, 2014 - 04:43:30
Django version 1.6.2, using settings 'settings'
Starting development server at http://0.0.0.0:8000/
Quit the server with CONTROL-C.
[25/May/2014 20:29:25] "GET /api/v1/test/?format=json HTTP/1.1" 500 1895
[25/May/2014 20:29:57] "GET /api/v1/test/? HTTP/1.1" 500 69
[25/May/2014 20:30:00] "GET /api/v1/test/ HTTP/1.1" 500 69
[25/May/2014 20:30:13] "GET /api/v1/test/?format=json&zip=123 HTTP/1.1" 200 101
[25/May/2014 20:31:40] "GET /api/v1/test/?format=json&zip=78613 HTTP/1.1" 500 1895
Validating models...

running with lxml.etree
0 errors found
May 25, 2014 - 20:29:17
Django version 1.6.2, using settings 'settings'
Starting development server at http://0.0.0.0:8000/
Quit the server with CONTROL-C.
[25/May/2014 20:34:16] "GET /api/v1/test/?format=json&zip=78613 HTTP/1.1" 500 2145
Validating models...

running with lxml.etree
0 errors found
May 25, 2014 - 20:34:14
Django version 1.6.2, using settings 'settings'
Starting development server at http://0.0.0.0:8000/
Quit the server with CONTROL-C.
[25/May/2014 20:34:41] "GET /api/v1/test/?format=json&zip=78613 HTTP/1.1" 200 117
Validating models...

running with lxml.etree
0 errors found
May 25, 2014 - 20:34:40
Django version 1.6.2, using settings 'settings'
Starting development server at http://0.0.0.0:8000/
Quit the server with CONTROL-C.
Unhandled exception in thread started by <function wrapper at 0x2325ed8>
Traceback (most recent call last):
  File "/usr/lib/python2.6/site-packages/django/utils/autoreload.py", line 93, in wrapper
    fn(*args, **kwargs)
  File "/usr/lib/python2.6/site-packages/django/core/management/commands/runserver.py", line 127, in inner_run
    ipv6=self.use_ipv6, threading=threading)
  File "/usr/lib/python2.6/site-packages/django/core/servers/basehttp.py", line 169, in run
    httpd.serve_forever()
  File "/usr/lib64/python2.6/SocketServer.py", line 224, in serve_forever
    r, w, e = select.select([self], [], [], poll_interval)
AttributeError: 'NoneType' object has no attribute 'select'
[25/May/2014 20:35:10] "GET /api/v1/test/?format=json&zip=78613 HTTP/1.1" 200 780
Validating models...

running with lxml.etree
0 errors found
May 25, 2014 - 20:35:08
Django version 1.6.2, using settings 'settings'
Starting development server at http://0.0.0.0:8000/
Quit the server with CONTROL-C.
[25/May/2014 20:35:56] "GET /api/v1/test/?format=json&zip=78613 HTTP/1.1" 500 1271
Validating models...

running with lxml.etree
0 errors found
May 25, 2014 - 20:35:54
Django version 1.6.2, using settings 'settings'
Starting development server at http://0.0.0.0:8000/
Quit the server with CONTROL-C.
[25/May/2014 20:38:40] "GET /api/v1/test/?format=json&zip=78613 HTTP/1.1" 200 780
Validating models...

running with lxml.etree
0 errors found
May 25, 2014 - 20:38:38
Django version 1.6.2, using settings 'settings'
Starting development server at http://0.0.0.0:8000/
Quit the server with CONTROL-C.
[25/May/2014 20:38:59] "GET /api/v1/test/?format=json&zip=78613 HTTP/1.1" 200 117
Validating models...

running with lxml.etree
0 errors found
May 25, 2014 - 20:38:58
Django version 1.6.2, using settings 'settings'
Starting development server at http://0.0.0.0:8000/
Quit the server with CONTROL-C.
[25/May/2014 20:39:17] "GET /api/v1/test/?format=json&zip=78613 HTTP/1.1" 500 1271
Validating models...

running with lxml.etree
0 errors found
May 25, 2014 - 20:39:16
Django version 1.6.2, using settings 'settings'
Starting development server at http://0.0.0.0:8000/
Quit the server with CONTROL-C.
[25/May/2014 20:40:59] "GET /api/v1/test/?format=json&zip=78613 HTTP/1.1" 500 2145
Validating models...

running with lxml.etree
0 errors found
May 25, 2014 - 20:40:55
Django version 1.6.2, using settings 'settings'
Starting development server at http://0.0.0.0:8000/
Quit the server with CONTROL-C.
[25/May/2014 20:41:30] "GET /api/v1/test/?format=json&zip=78613 HTTP/1.1" 500 2145
[25/May/2014 20:41:34] "GET /api/v1/test/?format=json&zip=78613 HTTP/1.1" 500 2145
Validating models...

running with lxml.etree
0 errors found
May 25, 2014 - 20:41:30
Django version 1.6.2, using settings 'settings'
Starting development server at http://0.0.0.0:8000/
Quit the server with CONTROL-C.
[25/May/2014 20:41:48] "GET /api/v1/test/?format=json&zip=78613 HTTP/1.1" 200 117
Validating models...

running with lxml.etree
0 errors found
May 25, 2014 - 20:41:47
Django version 1.6.2, using settings 'settings'
Starting development server at http://0.0.0.0:8000/
Quit the server with CONTROL-C.
[25/May/2014 20:42:33] "GET /api/v1/test/?format=json&zip=78613 HTTP/1.1" 500 2145
Validating models...

running with lxml.etree
0 errors found
May 25, 2014 - 20:42:13
Django version 1.6.2, using settings 'settings'
Starting development server at http://0.0.0.0:8000/
Quit the server with CONTROL-C.
Unhandled exception in thread started by <function wrapper at 0xe82ed8>
Traceback (most recent call last):
  File "/usr/lib/python2.6/site-packages/django/utils/autoreload.py", line 93, in wrapper
    fn(*args, **kwargs)
  File "/usr/lib/python2.6/site-packages/django/core/management/commands/runserver.py", line 127, in inner_run
    ipv6=self.use_ipv6, threading=threading)
  File "/usr/lib/python2.6/site-packages/django/core/servers/basehttp.py", line 169, in run
    httpd.serve_forever()
  File "/usr/lib64/python2.6/SocketServer.py", line 224, in serve_forever
    r, w, e = select.select([self], [], [], poll_interval)
AttributeError: 'NoneType' object has no attribute 'select'
[25/May/2014 20:43:33] "GET /api/v1/test/?format=json&zip=78613 HTTP/1.1" 200 231
Validating models...

running with lxml.etree
0 errors found
May 25, 2014 - 20:43:30
Django version 1.6.2, using settings 'settings'
Starting development server at http://0.0.0.0:8000/
Quit the server with CONTROL-C.
[25/May/2014 20:43:58] "GET /api/v1/test/?format=json&zip=78613 HTTP/1.1" 500 1271
[25/May/2014 20:44:00] "GET /api/v1/test/?format=json&zip=78613 HTTP/1.1" 500 1271
Validating models...

running with lxml.etree
0 errors found
May 25, 2014 - 20:43:56
Django version 1.6.2, using settings 'settings'
Starting development server at http://0.0.0.0:8000/
Quit the server with CONTROL-C.
[25/May/2014 20:48:15] "GET /api/v1/test/?format=json&lon=-97.8038&lat=30.4704&rang=30 HTTP/1.1" 400 54
Validating models...

running with lxml.etree
0 errors found
May 25, 2014 - 20:44:09
Django version 1.6.2, using settings 'settings'
Starting development server at http://0.0.0.0:8000/
Quit the server with CONTROL-C.
[25/May/2014 20:49:11] "GET /api/v1/test/?format=json&lon=-97.8038&lat=30.4704&rang=30 HTTP/1.1" 500 977
Validating models...

running with lxml.etree
0 errors found
May 25, 2014 - 20:49:11
Django version 1.6.2, using settings 'settings'
Starting development server at http://0.0.0.0:8000/
Quit the server with CONTROL-C.
[25/May/2014 20:49:33] "GET /api/v1/test/?format=json&lon=-97.8038&lat=30.4704&rang=30 HTTP/1.1" 500 1111
[25/May/2014 20:49:57] "GET /api/v1/test/?format=json&lon=-97.8038&lat=30.4704&range=30 HTTP/1.1" 200 1879
[25/May/2014 20:50:02] "GET /api/v1/test/?format=xml&lon=-97.8038&lat=30.4704&range=30 HTTP/1.1" 200 3616
Validating models...

running with lxml.etree
0 errors found
May 25, 2014 - 20:49:29
Django version 1.6.2, using settings 'settings'
Starting development server at http://0.0.0.0:8000/
Quit the server with CONTROL-C.
[25/May/2014 20:53:07] "GET /api/v1/test/?format=xml&lon=-97.8038&lat=30.4704&range=30 HTTP/1.1" 500 1018
Validating models...

running with lxml.etree
0 errors found
May 25, 2014 - 20:52:09
Django version 1.6.2, using settings 'settings'
Starting development server at http://0.0.0.0:8000/
Quit the server with CONTROL-C.
[25/May/2014 20:53:35] "GET /api/v1/test/?format=xml&lon=-97.8038&lat=30.4704&range=30 HTTP/1.1" 200 3616
[25/May/2014 20:53:44] "GET /api/v1/test/?format=json&lon=-97.8038&lat=30.4704&range=30 HTTP/1.1" 200 1879
[25/May/2014 20:54:28] "GET /api/v1/test/?format=json&lon=-97.8038&lat=30.4704&range=30 HTTP/1.1" 200 1879
Validating models...

running with lxml.etree
0 errors found
May 25, 2014 - 20:53:35
Django version 1.6.2, using settings 'settings'
Starting development server at http://0.0.0.0:8000/
Quit the server with CONTROL-C.
[25/May/2014 20:56:10] "GET /api/v1/test/?format=json&lon=-97.8038&lat=30.4704&range=30 HTTP/1.1" 200 3082
Validating models...

running with lxml.etree
0 errors found
May 25, 2014 - 20:56:08
Django version 1.6.2, using settings 'settings'
Starting development server at http://0.0.0.0:8000/
Quit the server with CONTROL-C.
[25/May/2014 20:56:39] "GET /api/v1/test/?format=json&lon=-97.8038&lat=30.4704&range=30 HTTP/1.1" 200 3097
[25/May/2014 20:56:50] "GET /api/v1/test/?format=xml&lon=-97.8038&lat=30.4704&range=30 HTTP/1.1" 200 4221
Validating models...

running with lxml.etree
0 errors found
May 25, 2014 - 20:56:36
Django version 1.6.2, using settings 'settings'
Starting development server at http://0.0.0.0:8000/
Quit the server with CONTROL-C.
[25/May/2014 20:57:32] "GET /api/v1/test/?format=json&lon=-97.8038&lat=30.4704&range=30 HTTP/1.1" 200 3082
Validating models...

running with lxml.etree
0 errors found
May 25, 2014 - 20:57:06
Django version 1.6.2, using settings 'settings'
Starting development server at http://0.0.0.0:8000/
Quit the server with CONTROL-C.
[25/May/2014 20:59:43] "GET /api/v1/test/?format=json&lon=-97.8038&lat=30.4704&range=30 HTTP/1.1" 200 443
Validating models...

running with lxml.etree
0 errors found
May 25, 2014 - 20:59:41
Django version 1.6.2, using settings 'settings'
Starting development server at http://0.0.0.0:8000/
Quit the server with CONTROL-C.
[25/May/2014 21:01:35] "GET /api/v1/test/?format=json&lon=-97.8038&lat=30.4704&range=30 HTTP/1.1" 500 994
Validating models...

running with lxml.etree
0 errors found
May 25, 2014 - 21:01:31
Django version 1.6.2, using settings 'settings'
Starting development server at http://0.0.0.0:8000/
Quit the server with CONTROL-C.
[25/May/2014 21:01:55] "GET /api/v1/test/?format=json&lon=-97.8038&lat=30.4704&range=30 HTTP/1.1" 500 1023
[25/May/2014 21:01:59] "GET /api/v1/test/?format=json&lon=-97.8038&lat=30.4704&range=30 HTTP/1.1" 500 1023
[25/May/2014 21:02:02] "GET /api/v1/test/?format=json&lon=-97.8038&lat=30.4704&range=30 HTTP/1.1" 500 1023
[25/May/2014 21:02:04] "GET /api/v1/test/?format=json&lon=-97.8038&lat=30.4704&range=30 HTTP/1.1" 500 1023
Validating models...

running with lxml.etree
0 errors found
May 25, 2014 - 21:01:54
Django version 1.6.2, using settings 'settings'
Starting development server at http://0.0.0.0:8000/
Quit the server with CONTROL-C.
[25/May/2014 21:07:50] "GET /api/v1/test/?format=json&lon=-97.8038&lat=30.4704&range=30 HTTP/1.1" 200 1879
[25/May/2014 21:08:02] "GET /api/v1/test/?format=xml&lon=-97.8038&lat=30.4704&range=30 HTTP/1.1" 200 3616
[25/May/2014 21:11:43] "GET /api/v1/test/?format=json&lon=-97.8038&lat=30.4704&range=30 HTTP/1.1" 200 1879
[25/May/2014 21:11:43] "GET /api/v1/test/?format=json&lon=-97.8038&lat=30.4704&range=30 HTTP/1.1" 200 1879
Validating models...

running with lxml.etree
0 errors found
May 25, 2014 - 21:07:48
Django version 1.6.2, using settings 'settings'
Starting development server at http://0.0.0.0:8000/
Quit the server with CONTROL-C.
[25/May/2014 21:17:56] "GET /api/v1/test/?format=json&lon=-97.8038&lat=30.4704&range=30 HTTP/1.1" 200 3082
[26/May/2014 11:57:19] code 400, message Bad request syntax ('\x00')
[26/May/2014 11:57:19] " " 400 -
[26/May/2014 11:57:21] "GET http://proxyjudge.info HTTP/1.1" 404 1657
[26/May/2014 11:57:23] code 400, message Bad request syntax ('\x04\x01\x00P\xa2\xd3\xe0\xac0\x00')
Traceback (most recent call last):
  File "/usr/lib64/python2.6/SocketServer.py", line 560, in process_request_thread
    self.finish_request(request, client_address)
  File "/usr/lib64/python2.6/SocketServer.py", line 322, in finish_request
    self.RequestHandlerClass(request, client_address, self)
  File "/usr/lib/python2.6/site-packages/django/core/servers/basehttp.py", line 126, in __init__
    super(WSGIRequestHandler, self).__init__(*args, **kwargs)
  File "/usr/lib64/python2.6/SocketServer.py", line 617, in __init__
    self.handle()
  File "/usr/lib64/python2.6/wsgiref/simple_server.py", line 131, in handle
    if not self.parse_request(): # An error code has been sent, just exit
  File "/usr/lib64/python2.6/BaseHTTPServer.py", line 289, in parse_request
    self.send_error(400, "Bad request syntax (%r)" % requestline)
  File "/usr/lib64/python2.6/BaseHTTPServer.py", line 357, in send_error
    self.send_response(code, message)
  File "/usr/lib64/python2.6/BaseHTTPServer.py", line 374, in send_response
    self.log_request(code)
  File "/usr/lib64/python2.6/BaseHTTPServer.py", line 411, in log_request
    self.requestline, str(code), str(size))
  File "/usr/lib/python2.6/site-packages/django/core/servers/basehttp.py", line 138, in log_message
    msg = "[%s] %s\n" % (self.log_date_time_string(), format % args)
UnicodeDecodeError: 'ascii' codec can't decode byte 0xa2 in position 5: ordinal not in range(128)
[26/May/2014 11:57:25] code 400, message Bad request syntax ('\x05\x01\x00')
[26/May/2014 11:57:25] " " 400 -
[26/May/2014 11:57:28] code 400, message Bad request syntax ('\x05\x01\x00')
[26/May/2014 11:57:28] " " 400 -
[28/May/2014 07:47:28] "GET /w00tw00t.at.ISC.SANS.DFind:) HTTP/1.1" 404 2119
[29/May/2014 19:03:34] "GET http://www.baidu.com/ HTTP/1.1" 404 1652
[30/May/2014 01:16:14] "GET /api/theatres/all/ HTTP/1.1" 404 2681
[31/May/2014 14:19:04] "GET /manager/html HTTP/1.1" 404 2041
[02/Jun/2014 16:29:32] "GET /w00tw00t.at.ISC.SANS.DFind:) HTTP/1.1" 404 2119
[23/Jun/2014 06:21:18] "GET http://www.google.com/ HTTP/1.0" 404 1656
[23/Jun/2014 18:35:34] "GET /manager/html HTTP/1.1" 404 2041
